Workbook
Name __TAB2: #REF!
Name __TAB2: #REF!
Name _TAB2: #REF!
Name _TAB2: #REF!
Name CARPETA: '[1]LIMITES '!$P$18:$R$37
Name DATOS: #REF!
Name DATOS: #REF!
Name DATOS2: #REF!
Name DATOS2: #REF!
Name FECTC: '[2]Marshall '!$C$53:$D$133
Name limite: #REF!
Name limite: #REF!
Name tabla: '[1]LIMITES '!$P$18:$R$37
Name TABLA2: #REF!
Name TABLA2: #REF!
Name tabla3: [3]LIMITES!$A$17

Sheet Datos
E3: DETERMINACIÓN DE PESO UNITARIO DE SUELOS CON ÍNDICE DE DENSIDAD MÍNIMO SEGÚN LA NORMA ASTM D4254 Laboratorio de Mecánica de Suelos
C8: Proyecto : | I8: Sondeo° :
C9: Localizacion : | I9: Numero de muestra N° :
C10: Fecha : | I10: Profundidad en metros m : | K10: a
C12: Características del Material
C13: Parametro analizado | F13: Resultado de laboratorio
C14: Material Retenido en Malla de 3", % | F14: =Granulometría!F23 -> #DIV/0!
C15: Material que Pasa la Malla No. 4, % | F15: =Granulometría!L23 -> #DIV/0!
C16: Material que Pasa la Malla No. 40, % | F16: =Granulometría!L27 -> #DIV/0!
C17: Material que Pasa la Malla No. 200, % | F17: =Granulometría!L30 -> #DIV/0!
C18: Fragmentos de Roca, % | F18: =Granulometría!L32 -> #DIV/0!
C19: Grava, % | F19: =Granulometría!L33 -> #DIV/0!
C20: Arena, % | F20: =Granulometría!L34 -> #DIV/0!
C21: Finos, % | F21: =Granulometría!L35 -> #DIV/0!
C22: Límite Líquido, % | F22: =Límites!N28 -> #VALUE!
C23: Límite Plástico, % | F23: =Límites!N29 -> #N/A
C24: Índice Plástico, % | F24: =Límites!N30 -> #VALUE!
C25: Límite de Contracción, % | F25: =Límites!N31 -> N/A
C26: Densidad relativa de sólidos | F26: =Gs!L42 -> 0
C27: Contenido de agua natural, % | F27: ='w%'!L7 -> #N/A
C28: Clasificación S.U.C.S. | F28: =Granulometría!F33 -> #DIV/0! | G28: =Granulometría!G33 -> #DIV/0!

Sheet w%
C3: DETERMINACION DE CONTENIDO DE AGUA (HUMEDAD), DE LA MASA DE SUELO ASTM D2216 | M3: Proyecto : | N3: =Datos!D8 -> 0
C4: Numero | E4: Profundidad Metros | G4: Longitud | H4: Datos de la Capsula | J4: Peso suelo+capsula | L4: Contenido | M4: Localizacion : | N4: =Datos!D9 -> 0
C5: Sondeo | D5: Muestra | E5: D | F5: A | G5: Centimetro | H5: Numero | I5: Peso | J5: Wsh+C | K5: Wss+C | L5: Natural | M5: Fecha : | N5: =Datos!D10 -> 0
C6: Nº | D6: Nº | E6: m | F6: m | G6: cm | H6: Nº | I6: gr | J6: gr | K6: gr | L6: % | M6: DESCRIPCION E IDENTIFICACION DE SUELOS (VISUAL Y MANUAL) ASTM D2488
C7: =Datos!J8 | D7: =Datos!J9 -> 0 | E7: =Datos!J10 -> 0 | F7: =Datos!L10 -> 0 | I7: =LOOKUP(H7,AA91:AB290) -> #N/A | L7: =((J7-K7)/(K7-I7)*100) -> #N/A
B8: =IF(C8="","",(B7+1))
B9: =IF(C9="","",(B8+1))
B10: =IF(C10="","",(B9+1))
B11: =IF(C11="","",(B10+1))
B12: =IF(C12="","",(B11+1))
B13: =IF(C13="","",(B12+1))
B14: =IF(C14="","",(B13+1))
B15: =IF(C15="","",(B14+1))
B16: =IF(C16="","",(B15+1))
B17: =IF(C17="","",(B16+1))
B18: =IF(C18="","",(B17+1))
B19: =IF(C19="","",(B18+1))
... B42: =IF(C42="","",(B41+1))
AA90: CAPSULA | AB90: PESO
AA91: 1 | AB91: 12.62
AA92: 2 | AB92: 13.11
AA93: 3 | AB93: 12.88
AA94: 4 | AB94: 12.87
AA95: 5 | AB95: 12.97
AA96: 6 | AB96: 13.2
AA97: 7 | AB97: 12.73
AA98: 8 | AB98: 13.2
AA99: 9 | AB99: 13.22
AA100: 10 | AB100: 13.33
AA101: 11 | AB101: 10.97
AA102: 12 | AB102: 11.1
... AA290: 200 | AB290: 11.06

Sheet MO
C3: DETERMINACION DE CONTENIDO DE MATERIA ORGÁNICA, DE LA MASA DE SUELO | M3: Proyecto : | N3: =[4]Datos!D8 -> Exploración Geotécnica Terracerías
C4: Numero | E4: Profundidad Metros | G4: Longitud | H4: Datos de la Capsula | J4: Peso suelo+capsula | L4: Contenido | M4: Localizacion : | N4: =[4]Datos!D9 -> KM 27+000 al 85+000, Tabasco
C5: Sondeo | D5: Muestra | E5: D | F5: A | G5: Centimetro | H5: Numero | I5: Peso | J5: Wsh+C | K5: Wss+C | L5: Natural | M5: Fecha : | N5: =[4]Datos!D10 -> 2026-01-05
C6: Nº | D6: Nº | E6: m | F6: m | G6: cm | H6: Nº | I6: gr | J6: gr | K6: gr | L6: % | M6: DESCRIPCION E IDENTIFICACION DE SUELOS (VISUAL Y MANUAL) ASTM D2488
C7: =Datos!J8 | D7: =Datos!J9 -> 0 | E7: =[4]Datos!J10 -> 0 | F7: =[4]Datos!L10 -> 0.60 | I7: =+VLOOKUP(H7,$C$65:$D$319, 2,FALSE) -> #N/A | L7: =((J7-K7)/(K7-I7)*100) -> #N/A
B8: =IF(C8="","",(B7+1))
B9: =IF(C9="","",(B8+1))
B10: =IF(C10="","",(B9+1))
B11: =IF(C11="","",(B10+1))
B12: =IF(C12="","",(B11+1))
B13: =IF(C13="","",(B12+1))
B14: =IF(C14="","",(B13+1))
B15: =IF(C15="","",(B14+1))
B16: =IF(C16="","",(B15+1))
B17: =IF(C17="","",(B16+1))
B18: =IF(C18="","",(B17+1))
B19: =IF(C19="","",(B18+1))
... B42: =IF(C42="","",(B41+1))
C62: Capsulas
C63: CAP No. | D63: Peso ( gr)
C65: 1 | D65: 12.12
C66: 2 | D66: 12.58
C67: 3 | D67: 12.45
C68: 4 | D68: 12.42
C69: 5 | D69: 12.11
C70: 6 | D70: 13.21
C71: 7 | D71: 13.83
C72: 8 | D72: 12.45
C73: 9 | D73: 12.93
C74: 10 | D74: 13.11
C75: 11 | D75: 12.1
C76: 12 | D76: 11.72
... C319: 255 | D319: 12.23

Sheet Gs
D3: DETERMINACIÓN DE GRAVEDAD ESPECÍFICA SEGÚN LA NORMA ASTM C128 Laboratorio de Mecánica de Suelos
C8: Proyecto : | D8: =Datos!D8 -> 0 | K8: Sondeo N° : | L8: =Datos!J8
C9: Localizacion : | D9: =Datos!D9 -> 0 | K9: Muestra N° : | L9: =Datos!J9 -> 0
C10: Fecha : | D10: =Datos!D10 -> 0 | K10: Profundidad m : | L10: =CONCATENATE(Datos!J10," ",Datos!K10," ",Datos!L10) -> a
C14: Calibración de matraz 1
C15: Temp. Sup. (°C) | D15: Temp. Med. (°C) | E15: Temp. Inf. (°C) | F15: Temp. Prom. (°C) | G15: Peso Wfw (g)
F16: =AVERAGE(C16:E16) -> #DIV/0!
F17: =AVERAGE(C17:E17) -> #DIV/0!
F18: =AVERAGE(C18:E18) -> #DIV/0!
F19: =AVERAGE(C19:E19) -> #DIV/0!
F20: =AVERAGE(C20:E20) -> #DIV/0!
D21: Constantes de la ecuación
D22: t2 | E22: t1 | F22: t0
D23: - | E23: -
C27: Calibración de matraz 2
C28: Temp. Sup. (°C) | D28: Temp. Med. (°C) | E28: Temp. Inf. (°C) | F28: Temp. Prom. (°C) | G28: Peso Wfw (g) | Q28: =(-0.0019*(E40)^2)-(0.0206*(E40))+679.19 -> 679.19 | R28: =(-0.0023*(E40)^2)-(0.0014*(E40))+689.61 -> 689.61
F29: =AVERAGE(C29:E29) -> #DIV/0!
F30: =AVERAGE(C30:E30) -> #DIV/0!
F31: =AVERAGE(C31:E31) -> #DIV/0!
F32: =AVERAGE(C32:E32) -> #DIV/0!
F33: =AVERAGE(C33:E33) -> #DIV/0!
D34: Constantes de la ecuación
D35: t2 | E35: t1 | F35: t0
D36: - | E36: -
D39: Matraz | E39: Temp. (°C) | F39: Wfw (g) | G39: Wfws (g) | H39: Tara No. | I39: Wt (g) | J39: Wt+s (g) | K39: Ws (g) | L39: Densidad relativa de sólidos
F40: =IF(D40=1, Q28, R28) -> 689.61 | H40: - | I40: 0 | K40: =J40-I40 -> 0 | L40: =K40/(F40+K40-G40) -> 0
F41: =IF(D41=1, Q29, R29) -> 0
J42: Promedio | L42: =AVERAGE(L40:L41) -> 0

Sheet Granulometría
E3: ANALISIS GRANULOMETRICO NORMA ASTM D422 Laboratorio de Mecanica de Suelos
D8: Proyecto : | E8: =Datos!D8 -> 0
D9: Localizacion : | E9: =Datos!D9 -> 0
D10: Fecha : | E10: =Datos!D10 -> 0
D12: Numero de Sondeo N° : | E12: =Datos!J8 | I12: Peso húmedo mat que pasa No. 4 gr : | J12: =E14 -> 0
D13: Numero de Muestra N° : | E13: =Datos!J9 -> 0 | I13: Peso de la tara gr : | J13: 0
C14: Peso de la muestra inicial: | I14: Peso seco mat que pasa No. 4 gr : | J14: =E14 -> 0
C15: Retenido No. 4 gr : | E15: =SUM(E23:E30,J23) -> 0 | I15: Contenido de agua mat que pasa No. 4: | J15: =((J12-J14)/(J14-J13))*100 -> #DIV/0!
D16: Mat. que pasa No. 4 gr : | E16: =E14-E15 -> 0 | I16: Mat. que pasa No. 4 corregido gr : | J16: =ROUND(E16/(1+(J15/100)),3) -> #DIV/0!
D17: Muestra total corregida gr : | E17: =E15+J16 -> #DIV/0! | I17: Peso submuestra 2 gr : | J17: =J16 -> #DIV/0!
C19: MATERIAL CRIBADO MALLA 3" Y RETENIDO MALLA N°4 | H19: MATERIAL CRIBADO MALLA N°4 Y RETENIDO MALLA N°200
C20: Datos de las mallas | E20: Peso del suelo/material | G20: Acumulativo | H20: Datos de las mallas | J20: Peso del suelo/material | L20: Acumulativo
C21: Pulgada | D21: Abertura | E21: Retenido | F21: Parcial | G21: que pasa | H21: Numero | I21: Abertura | J21: Retenido | K21: Parcial | L21: que pasa
C22: in | D22: mm | E22: gr | F22: % | G22: % | H22: N° | I22: mm | J22: gr | K22: % | L22: %
C23: =IF(D23="","",("3")) | D23: =IF(E23="","",(76.2)) | F23: =(E23/$E$17*100) -> #DIV/0! | G23: =(100-F23) -> #DIV/0! | H23: =IF(I23="","",(4)) | I23: =IF(J23="","",(4.76)) | K23: =(J23/$E$17*100) -> #DIV/0! | L23: =G30-K23 -> #DIV/0!
C24: =IF(D24="","",("2")) | D24: =IF(E24="","",(50)) | F24: =(E24/$E$17*100) -> #DIV/0! | G24: =G23-F24 -> #DIV/0! | H24: Submuestra 2 | P24: =Límites!R18 -> #VALUE! | Q24: =Límites!S18 -> #VALUE!
C25: =IF(D25="","",("1 1/2")) | D25: =IF(E25="","",(38.1)) | F25: =(E25/$E$17*100) -> #DIV/0! | G25: =G24-F25 -> #DIV/0! | H25: =IF(I25="","",(10)) | I25: =IF(J25="","",(2)) | K25: =(J25/$J$17*100)*($J$16/$E$17) -> #DIV/0! | L25: =L23-K25 -> #DIV/0!
C26: =IF(D26="","",("1")) | D26: =IF(E26="","",(25.4)) | F26: =(E26/$E$17*100) -> #DIV/0! | G26: =G25-F26 -> #DIV/0! | H26: =IF(I26="","",(20)) | I26: =IF(J26="","",(0.85)) | K26: =(J26/$J$17*100)*($J$16/$E$17) -> #DIV/0! | L26: =L25-K26 -> #DIV/0! | P26: =IF(L33>L34, "G", "S") -> #DIV/0! | Q26: =IF(L34>L35, P24, Q24) -> #DIV/0!
C27: =IF(D27="","",("3/4")) | D27: =IF(E27="","",(19.1)) | F27: =(E27/$E$17*100) -> #DIV/0! | G27: =G26-F27 -> #DIV/0! | H27: =IF(I27="","",(40)) | I27: =IF(J27="","",(0.425)) | K27: =(J27/$J$17*100)*($J$16/$E$17) -> #DIV/0! | L27: =L26-K27 -> #DIV/0!
C28: =IF(D28="","",("1/2")) | D28: =IF(E28="","",(12.7)) | F28: =(E28/$E$17*100) -> #DIV/0! | G28: =G27-F28 -> #DIV/0! | H28: =IF(I28="","",(60)) | I28: =IF(J28="","",(0.25)) | K28: =(J28/$J$17*100)*($J$16/$E$17) -> #DIV/0! | L28: =L27-K28 -> #DIV/0!
C29: =IF(D29="","",("3/8")) | D29: =IF(E29="","",(9.525)) | F29: =(E29/$E$17*100) -> #DIV/0! | G29: =G28-F29 -> #DIV/0! | H29: =IF(I29="","",(100)) | I29: =IF(J29="","",(0.15)) | K29: =(J29/$J$17*100)*($J$16/$E$17) -> #DIV/0! | L29: =L28-K29 -> #DIV/0!
C30: =IF(D30="","",("1/4")) | D30: =IF(E30="","",(6.635)) | F30: =(E30/$E$17*100) -> #DIV/0! | G30: =G29-F30 -> #DIV/0! | H30: =IF(I30="","",(200)) | I30: =IF(J30="","",(0.074)) | K30: =(J30/$J$17*100)*($J$16/$E$17) -> #DIV/0! | L30: =L29-K30 -> #DIV/0!
E32: Material Predominante : | I32: D10 mm : | J32: =IF(L35>12,"N/A","Definir gráficamente") -> #DIV/0! | K32: > 3" % : | L32: =F23 -> #DIV/0!
E33: Simbolo de Grupo : | F33: =IF(L34>L35, P26, P24) -> #DIV/0! | G33: =Q26 -> #DIV/0! | I33: D30 mm : | J33: =IF(L35>12,"N/A","Definir gráficamente") -> #DIV/0! | K33: Grava % : | L33: =G23-L23 -> #DIV/0!
E34: Clasificación S.U.C.S. : | I34: D60 mm : | J34: =IF(L35>12,"N/A","Definir gráficamente") -> #DIV/0! | K34: Arena % : | L34: =L23-L30 -> #DIV/0!
E35: Grava Bien Graduada GW : | I35: Cu = D60/D10 : | J35: =IF(L35>12,"N/A",J34/J32) -> #DIV/0! | K35: Finos % : | L35: =L30 -> #DIV/0!
E36: Arena Bien Graduada SW : | I36: Cc = (D302)/D10*D60 : | J36: =IF(L35>12,"N/A",(J33*J33)/(J32*J34)) -> #DIV/0! | K36: Suma : | L36: =IF(L35="","",(SUM(L32:L35))) -> #DIV/0!
D39: =IF(D23="","",(D23)) | E39: =IF(G23="","",(G23)) -> #DIV/0! | F39: 100 | G39: 100 | H39: 4.76 | I39: 100 | J39: =IF(I23="","",(I23)) | K39: =IF(L23="","",(L23)) -> #DIV/0!
D40: =IF(D39="","",(D39)) | E40: 0 | F40: 4.76 | G40: 100 | H40: 0.074 | I40: 100 | J40: =IF(J39="","",(J39)) | K40: 0
D41: =IF(D24="","",(D24)) | E41: =IF(G24="","",(G24)) -> #DIV/0! | J41: =IF(I25="","",(I25)) | K41: =IF(L25="","",(L25)) -> #DIV/0!
D42: =IF(D41="","",(D41)) | E42: 0 | F42: 0.074 | G42: 100 | J42: =IF(J41="","",(J41)) | K42: 0
D43: =IF(D25="","",(D25)) | E43: =IF(G25="","",(G25)) -> #DIV/0! | F43: 0.01 | G43: 100 | J43: =IF(I26="","",(I26)) | K43: =IF(L26="","",(L26)) -> #DIV/0!
D44: =IF(D43="","",(D43)) | E44: 0 | J44: =IF(J43="","",(J43)) | K44: 0
D45: =IF(D26="","",(D26)) | E45: =IF(G26="","",(G26)) -> #DIV/0! | J45: =IF(I27="","",(I27)) | K45: =IF(L27="","",(L27)) -> #DIV/0!
D46: =IF(D45="","",(D45)) | E46: 0 | J46: =IF(J45="","",(J45)) | K46: 0
D47: =IF(D27="","",(D27)) | E47: =IF(G27="","",(G27)) -> #DIV/0! | J47: =IF(I28="","",(I28)) | K47: =IF(L28="","",(L28)) -> #DIV/0!
D48: =IF(D47="","",(D47)) | E48: 0 | J48: =IF(J47="","",(J47)) | K48: 0
D49: =IF(D28="","",(D28)) | E49: =IF(G28="","",(G28)) -> #DIV/0! | J49: =IF(I29="","",(I29)) | K49: =IF(L29="","",(L29)) -> #DIV/0!
D50: =IF(D49="","",(D49)) | E50: 0 | J50: =IF(J49="","",(J49)) | K50: 0
D51: =IF(D29="","",(D29)) | E51: =IF(G29="","",(G29)) -> #DIV/0! | J51: =IF(I30="","",(I30)) | K51: =IF(L30="","",(L30)) -> #DIV/0!
...

Sheet Límites
E3: DETERMINACION DEL LIMITE LIQUIDO LIMITE PLASTICO E INDICE DE PLASTICIDAD ASTM D4318 Laboratorio de Mecánica de Suelos
D8: Proyecto : | E8: =Datos!D8 -> 0 | L8: Sondeo N° : | M8: =Datos!J8
D9: Localizacion : | E9: =Datos!D9 -> 0 | L9: Muestra N° : | M9: =Datos!J9 -> 0
D10: Fecha : | E10: =Datos!D10 -> 0 | L10: Profundidad m : | M10: =CONCATENATE(Datos!J10," ",Datos!K10," ",Datos!L10) -> a
C12: LÍMITE LÍQUIDO | F12: COPA DE CASAGRANDE | L12: CLASIFICACIÓN S.U.C.S.
C13: No. de golpes | D13: No. de tara | E13: Wt | F13: Wt+sh | G13: Wt+ss | H13: Ww | I13: Wss | J13: ω | L13: =CONCATENATE(Granulometría!F33,Granulometría!G33," - ",Granulometría!F34) -> #DIV/0!
E15: g | F15: g | G15: g | H15: g | I15: g | J15: %
E16: =LOOKUP(D16, $Z$91:$AA$290) -> #N/A | H16: =F16-G16 -> 0 | I16: =G16-E16 -> #N/A | J16: =(H16/I16)*100 -> #N/A
E17: =LOOKUP(D17, $Z$91:$AA$290) -> #N/A | H17: =F17-G17 -> 0 | I17: =G17-E17 -> #N/A | J17: =(H17/I17)*100 -> #N/A
E18: =LOOKUP(D18, $Z$91:$AA$290) -> #N/A | H18: =F18-G18 -> 0 | I18: =G18-E18 -> #N/A | J18: =(H18/I18)*100 -> #N/A | R18: =IF(N30>=V23,"C","M") -> #VALUE! | S18: =IF(N28>=50,"H","L") -> #VALUE!
E19: =LOOKUP(D19, $Z$91:$AA$290) -> #N/A | H19: =F19-G19 -> 0 | I19: =G19-E19 -> #N/A | J19: =(H19/I19)*100 -> #N/A | R19: =IF(R18="C","Arcilla", "Limo") -> #VALUE! | S19: =IF(S18="H","de alta deformabilidad", "de baja deformabilidad") -> #VALUE!
C21: LÍMITE PLÁSTICO | L21: CONTRACCIÓN LINEAL
C22: No. de tara | D22: Wt | E22: Wt+sh | F22: Wt+ss | G22: Ww | H22: Wss | I22: ω | L22: No. de barra | M22: Linicial | N22: Lfinal | O22: LC
V23: =0.73*(N28-20) -> #VALUE!
D24: g | E24: g | F24: g | G24: g | H24: g | I24: % | M24: cm | N24: cm | O24: %
D25: =LOOKUP(C25, $Z$91:$AA$290) -> #N/A | G25: =E25-F25 -> 0 | H25: =F25-D25 -> #N/A | I25: =(G25/H25)*100 -> #N/A | L25: - | O25: N/A
D26: =LOOKUP(C26, $Z$91:$AA$290) -> #N/A | G26: =E26-F26 -> 0 | H26: =F26-D26 -> #N/A | I26: =(G26/H26)*100 -> #N/A
S27: Para dibujo de líneas auxiliares
C28: Clasificación S.U.C.S. parte fina: | H28: =R19 -> #VALUE! | I28: =S19 -> #VALUE! | M28: Límite Líquido (LL) : | N28: =TREND(J16:J19,LOG10(C16:C19),LOG10(25)) -> #VALUE! | Q28: sx sx
C29: Según Terzaghi y Peck, el Material es de: | G29: =IF(N28<3,"Baja Plasticidad",IF(N28<50,"Plasticidad Intermedia",IF(N28<100,"Alta Plasticidad",IF(N28<200,"Muy Alta Plasticidad",IF(N28<500,"Extremadamente Alta Plasticidad"))))) -> #VALUE! | M29: Límite Plástico (LP) : | N29: =AVERAGE(I25:I26) -> #N/A | S29: 25 | T29: 0
C30: y de: | G30: =IF(0.009*(N28-10)<0.3,"Baja Compresibilidad",IF(0.009*(N28-10)<0.5,"Media Compresibilidad",IF(0.009*(N28-10)<0.1,"Alta Compresibilidad",IF(0.009*(N28-10)<10,"Muy Alta Compresibilidad",IF(0.009*(N28-10)<20,"Extremadamente Alta Compresibilidad"))))) -> #VALUE! | M30: Índice de Plasticidad (IP) : | N30: =N28-N29 -> #VALUE! | S30: 50 | T30: 0
C31: Índice de Consistencia Ic : | G31: =(N28-N32)/N30 -> #VALUE! | H31: =IF(G31>1,"Media Dura , Sólida",IF(G31>0.75,"Plástica",IF(G31>0.5,"Suave",IF(G31>0.25,"Semiliquida",IF(G31>0,"Viscosa","Consistencia Líquida"))))) -> #VALUE! | M31: Límite de Contracción (LC) : | N31: N/A
C32: Densidad relativa de sólidos: | G32: =Gs!L42 -> 0 | M32: Contenido Natural (Wn) : | N32: ='w%'!L7 -> #N/A | S32: 50 | T32: 200
D34: DENSIDAD DE SÓLIDOS | R34: LINEA U | S34: 8 | T34: =0.9*(S34-8) -> 0
S35: 120 | T35: =0.9*(S35-8) -> 100.8
R37: LÍNEA A | S37: =(4/0.73)+20 -> 25.479452 | T37: =0.73*(S37-20) -> 4
S38: 120 | T38: =0.73*(S38-20) -> 73
S40: =(4/0.9)+8 -> 12.444444 | T40: 4
S41: =S37 -> 25.479452 | T41: 4
S42: =(7/0.9)+8 -> 15.777778 | T42: 7
S43: =(7/0.73)+20 -> 29.589041 | T43: 7
S47: Solo mover lo rojo para ajustar gráficas
S48: 25 | T48: 62
S49: 25 | T49: 72.27
S51: 10 | T51: =TREND(J16:J19,LOG10(C16:C19),LOG10(25)) -> #VALUE!
S52: 25 | T52: =TREND(J16:J19,LOG10(C16:C19),LOG10(25)) -> #VALUE!
Z90: CAPSULA | AA90: PESO
Z91: 1 | AA91: 12.62
Z92: 2 | AA92: 13.11
Z93: 3 | AA93: 12.88
...
